<?xml version="1.0"?>
<robot xmlns:xacro="http://www.ros.org/wiki/xacro" >

    <xacro:include filename="inertial_macros.xacro" />

    <material name="white">
        <color rgba="1 1 1 1" />
    </material>

    <material name="orange">
        <color rgba="1 0.3 0.1 1"/>
    </material>

    <material name="blue">
        <color rgba="0.2 0.2 1 1"/>
    </material>

    <material name="black">
        <color rgba="0 0 0 1"/>
    </material>

    <material name="red">
        <color rgba="1 0 0 1"/>
    </material>

    <material name="green">
        <color rgba="0 1 0 1"/>
    </material>

    <material name="yellow">
        <color rgba="255 190 0 0.8"/>
    </material>
    
    <!-- BASE LINK -->
    <link name="base_link"></link>
    <link name="chassis">
         <visual>
             <origin xyz="0 0 0" rpy="0 0 0"/>
             <geometry>
                 <mesh filename = "file://$(find articubot_one)/description/DaeFile/Body.dae" scale = "1 1 1"/>
             </geometry>
             <material name="white"/>
         </visual>
         <collision> 
             <origin xyz="0 0 0" rpy="0 0 0"/>
             <geometry>
                 <mesh filename = "file://$(find articubot_one)/description/DaeFile/Body.dae" scale = "1 1 1"/>
             </geometry>
         </collision>
         <xacro:inertial_box mass="100" x="0.8" y="0.8" z="0.5"> 
             <origin xyz="0 0 0.25" rpy="0 0 0"/> 
         </xacro:inertial_box>
    </link>
    <gazebo reference="chassis">
         <material>Gazebo/White</material>
    </gazebo>
 
    <!-- BASE_FOOTPRINT LINK -->
    <joint name="base_footprint_joint" type="fixed">
         <parent link="base_link"/>
         <child link="base_footprint"/>
         <origin xyz="0 0 0" rpy="0 0 0"/>
         <dynamics damping="1" friction="500"/>
    </joint>
    <link name="base_footprint"></link>
    <joint name="chassis_joint" type="fixed">
         <parent link="base_link"/> 
         <child link="chassis"/> 
         <origin xyz="-0.1 0 0"/> 
    </joint>

    <!--WHEEL DESCRIPTION-->
    <!--Front Wheel-->
    <joint name="right_front_wheel_joint" type="continuous">
        <parent link="base_link"/>
        <child link="right_front_wheel"/>
        <origin xyz="0.125 0.45 0" rpy="-${pi/2} 0 0"/>
        <axis xyz="0 0 1"/>
        <dynamics damping="1" friction="10"/>
    </joint>

    <link name="right_front_wheel">
        <visual>
            <geometry>
                <cylinder length="0.1" radius="0.125" />
            </geometry>
            <material name="red"/>
        </visual>
        <collision>
            <geometry>
                <cylinder length="0.1" radius="0.125" />
            </geometry>
        </collision>
        <xacro:inertial_cylinder mass="1" length="0.1" radius="0.125">
            <origin xyz="0 0 0" rpy="0 0 0"/>
        </xacro:inertial_cylinder>
    </link>
    <gazebo reference="right_front_wheel">
        <material>Gazebo/Red</material>
    </gazebo>

    <joint name="left_front_wheel_joint" type="continuous">
        <parent link="base_link"/>
        <child link="left_front_wheel"/>
        <origin xyz="0.125 -0.45 0" rpy="${pi/2} 0 0"/>
        <axis xyz="0 0 1"/>
        <dynamics damping="1" friction="10"/>
    </joint>

    <link name="left_front_wheel">
        <visual>
            <geometry>
                <cylinder length="0.1" radius="0.125" />
            </geometry>
            <material name="blue"/>
        </visual>
        <collision>
            <geometry>
                <cylinder length="0.1" radius="0.125" />
            </geometry>
        </collision>
        <xacro:inertial_cylinder mass="1" length="0.1" radius="0.125">
            <origin xyz="0 0 0" rpy="0 0 0"/>
        </xacro:inertial_cylinder>
    </link>
    <gazebo reference="left_front_wheel">
        <material>Gazebo/Blue</material>
    </gazebo>

    <!--Back Wheel-->
    <joint name="right_back_wheel_joint" type="continuous">
        <parent link="base_link"/>
        <child link="right_back_wheel"/>
        <origin xyz="-0.325 0.45 0" rpy="-${pi/2} 0 0"/>
        <axis xyz="0 0 1"/>
        <dynamics damping="1" friction="10"/>
    </joint>

    <link name="right_back_wheel">
        <visual>
            <geometry>
                <cylinder length="0.1" radius="0.125" />
            </geometry>
            <material name="red"/>
        </visual>
        <collision>
            <geometry>
                <cylinder length="0.1" radius="0.125" />
            </geometry>
        </collision>
        <xacro:inertial_cylinder mass="1" length="0.1" radius="0.125">
            <origin xyz="0 0 0" rpy="0 0 0"/>
        </xacro:inertial_cylinder>
    </link>
    <gazebo reference="right_back_wheel">
        <material>Gazebo/Red</material>
    </gazebo>

    <joint name="left_back_wheel_joint" type="continuous">
        <parent link="base_link"/>
        <child link="left_back_wheel"/>
        <origin xyz="-0.325 -0.45 0" rpy="${pi/2} 0 0"/>
        <axis xyz="0 0 1"/>
        <dynamics damping="1" friction="10"/>
    </joint>

    <link name="left_back_wheel">
        <visual>
            <geometry>
                <cylinder length="0.1" radius="0.125" />
            </geometry>
            <material name="blue"/>
        </visual>
        <collision>
            <geometry>
                <cylinder length="0.1" radius="0.125" />
            </geometry>
        </collision>
        <xacro:inertial_cylinder mass="1" length="0.1" radius="0.125">
            <origin xyz="0 0 0" rpy="0 0 0"/>
        </xacro:inertial_cylinder>
    </link>
    <gazebo reference="left_back_wheel">
        <material>Gazebo/Blue</material>
    </gazebo>

    <!--ARM SLIDER PREFERENCE-->
    <joint name="arm_slider_joint" type="prismatic">
        <parent link="base_link"/>
        <child link="arm_slider"/>
        <origin xyz="0.2 0 0.25" rpy="0 0 0"/>
        <axis xyz="1 0 0"/>
        <limit lower="-0.155" upper="0.07" effort="0.00005" velocity="1"/>
        <dynamics damping="1" friction="50"/>
    </joint>

    <link name="arm_slider">
        <visual>    
            <geometry>
                <mesh filename = "file://$(find articubot_one)/description/DaeFile/Arm.dae" scale = "1 1 1"/>
            </geometry>
            <material name="black"/>
        </visual>
        <collision>
            <geometry>
                <mesh filename = "file://$(find articubot_one)/description/DaeFile/Arm.dae" scale = "1 1 1"/>
            </geometry>
        </collision>
        <xacro:inertial_box mass="0.5" x="0.3" y="0.25" z="0.25">
             <origin xyz="0.15 0 0" rpy="0 0 0"/>
        </xacro:inertial_box>
    </link>
    <gazebo reference="arm_slider">
        <material>Gazebo/Black</material>
    </gazebo>

    <!--Lifter DESCRIPTION-->
    <joint name="lifter_joint" type="prismatic">
        <parent link="arm_slider"/>
        <child link="lifter"/>
        <origin xyz="0.3 0 0.125" rpy="0 0 0"/>
        <axis xyz="0 0 1"/>
        <limit lower="-0.23" upper="0.145" effort="1" velocity="1"/>
        <dynamics damping="1" friction="150" />
    </joint>

    <link name="lifter">
        <visual>    
            <geometry>
                <mesh filename = "file://$(find articubot_one)/description/DaeFile/Lifter.dae" scale = "1 1 1"/>
            </geometry>
            <material name="yellow"/>
        </visual>
        <collision>
            <geometry>
                <mesh filename = "file://$(find articubot_one)/description/DaeFile/Lifter.dae" scale = "1 1 1"/>
            </geometry>
        </collision>
        <xacro:inertial_box mass="0.5" x="0.875" y="0.8" z="0.5">
             <origin xyz="0.415 0 0" rpy="0 0 0"/>
        </xacro:inertial_box>
    </link>
    <gazebo reference="lifter">
        <material>Gazebo/Yellow</material>
    </gazebo>
</robot>